2018-10-13 16:19:27,870 ERROR: Exception on /index [GET] [in D:\Programs\Python\Python37\lib\site-packages\flask\app.py:1761]
Traceback (most recent call last):
  File "D:\Programs\Python\Python37\lib\site-packages\flask\app.py", line 2292, in wsgi_app
    response = self.full_dispatch_request()
  File "D:\Programs\Python\Python37\lib\site-packages\flask\app.py", line 1815, in full_dispatch_request
    rv = self.handle_user_exception(e)
  File "D:\Programs\Python\Python37\lib\site-packages\flask\app.py", line 1718, in handle_user_exception
    reraise(exc_type, exc_value, tb)
  File "D:\Programs\Python\Python37\lib\site-packages\flask\_compat.py", line 35, in reraise
    raise value
  File "D:\Programs\Python\Python37\lib\site-packages\flask\app.py", line 1813, in full_dispatch_request
    rv = self.dispatch_request()
  File "D:\Programs\Python\Python37\lib\site-packages\flask\app.py", line 1799, in dispatch_request
    return self.view_functions[rule.endpoint](**req.view_args)
  File "D:\Programs\Python\Python37\lib\site-packages\flask_login\utils.py", line 261, in decorated_view
    return func(*args, **kwargs)
  File "D:\PycharmProjects\flask_mega\microblog09\app_name\routes.py", line 23, in index
    posts = current_user.followed_posts().all()
  File "D:\PycharmProjects\flask_mega\microblog09\app_name\models.py", line 60, in followed_posts
    own = Post.query.filter(user_id=self.id)
TypeError: filter() got an unexpected keyword argument 'user_id'
2018-10-13 16:19:52,686 ERROR: Exception on /index [GET] [in D:\Programs\Python\Python37\lib\site-packages\flask\app.py:1761]
Traceback (most recent call last):
  File "D:\Programs\Python\Python37\lib\site-packages\flask\app.py", line 2292, in wsgi_app
    response = self.full_dispatch_request()
  File "D:\Programs\Python\Python37\lib\site-packages\flask\app.py", line 1815, in full_dispatch_request
    rv = self.handle_user_exception(e)
  File "D:\Programs\Python\Python37\lib\site-packages\flask\app.py", line 1718, in handle_user_exception
    reraise(exc_type, exc_value, tb)
  File "D:\Programs\Python\Python37\lib\site-packages\flask\_compat.py", line 35, in reraise
    raise value
  File "D:\Programs\Python\Python37\lib\site-packages\flask\app.py", line 1813, in full_dispatch_request
    rv = self.dispatch_request()
  File "D:\Programs\Python\Python37\lib\site-packages\flask\app.py", line 1799, in dispatch_request
    return self.view_functions[rule.endpoint](**req.view_args)
  File "D:\Programs\Python\Python37\lib\site-packages\flask_login\utils.py", line 261, in decorated_view
    return func(*args, **kwargs)
  File "D:\PycharmProjects\flask_mega\microblog09\app_name\routes.py", line 23, in index
    posts = current_user.followed_posts().all()
  File "D:\PycharmProjects\flask_mega\microblog09\app_name\models.py", line 60, in followed_posts
    own = Post.query.filter(user_id=self.id)
TypeError: filter() got an unexpected keyword argument 'user_id'
2018-10-13 16:26:14,064 INFO: Microblog startup [in D:\PycharmProjects\flask_mega\microblog09\app_name\__init__.py:28]
2018-10-13 16:26:37,681 ERROR: Exception on /index [POST] [in D:\Programs\Python\Python37\lib\site-packages\flask\app.py:1761]
Traceback (most recent call last):
  File "D:\Programs\Python\Python37\lib\site-packages\flask\app.py", line 2292, in wsgi_app
    response = self.full_dispatch_request()
  File "D:\Programs\Python\Python37\lib\site-packages\flask\app.py", line 1815, in full_dispatch_request
    rv = self.handle_user_exception(e)
  File "D:\Programs\Python\Python37\lib\site-packages\flask\app.py", line 1718, in handle_user_exception
    reraise(exc_type, exc_value, tb)
  File "D:\Programs\Python\Python37\lib\site-packages\flask\_compat.py", line 35, in reraise
    raise value
  File "D:\Programs\Python\Python37\lib\site-packages\flask\app.py", line 1813, in full_dispatch_request
    rv = self.dispatch_request()
  File "D:\Programs\Python\Python37\lib\site-packages\flask\app.py", line 1799, in dispatch_request
    return self.view_functions[rule.endpoint](**req.view_args)
  File "D:\Programs\Python\Python37\lib\site-packages\flask_login\utils.py", line 261, in decorated_view
    return func(*args, **kwargs)
  File "D:\PycharmProjects\flask_mega\microblog09\app_name\routes.py", line 18, in index
    post = Post(body=form.post.data, author=current_user)
  File "<string>", line 4, in __init__
  File "D:\Programs\Python\Python37\lib\site-packages\sqlalchemy\orm\state.py", line 424, in _initialize_instance
    manager.dispatch.init_failure(self, args, kwargs)
  File "D:\Programs\Python\Python37\lib\site-packages\sqlalchemy\util\langhelpers.py", line 66, in __exit__
    compat.reraise(exc_type, exc_value, exc_tb)
  File "D:\Programs\Python\Python37\lib\site-packages\sqlalchemy\util\compat.py", line 249, in reraise
    raise value
  File "D:\Programs\Python\Python37\lib\site-packages\sqlalchemy\orm\state.py", line 421, in _initialize_instance
    return manager.original_init(*mixed[1:], **kwargs)
  File "D:\Programs\Python\Python37\lib\site-packages\sqlalchemy\ext\declarative\base.py", line 746, in _declarative_constructor
    (k, cls_.__name__))
TypeError: 'author' is an invalid keyword argument for Post
2018-10-13 16:36:39,548 INFO: Microblog startup [in D:\PycharmProjects\flask_mega\microblog09\app_name\__init__.py:28]
2018-10-13 16:36:57,930 INFO: Microblog startup [in D:\PycharmProjects\flask_mega\microblog09\app_name\__init__.py:28]
