2018-10-07 17:09:06,214 INFO: Microblog startup [in D:\PycharmProjects\flask_mega\microblog06\app_name\__init__.py:28]
2018-10-07 17:09:21,833 ERROR: Exception on /editprofile [POST] [in D:\Programs\Python\Python37\lib\site-packages\flask\app.py:1761]
Traceback (most recent call last):
  File "D:\Programs\Python\Python37\lib\site-packages\sqlalchemy\engine\base.py", line 1193, in _execute_context
    context)
  File "D:\Programs\Python\Python37\lib\site-packages\sqlalchemy\engine\default.py", line 509, in do_execute
    cursor.execute(statement, parameters)
  File "D:\Programs\Python\Python37\lib\site-packages\mysql\connector\cursor.py", line 566, in execute
    self._handle_result(self._connection.cmd_query(stmt))
  File "D:\Programs\Python\Python37\lib\site-packages\mysql\connector\connection.py", line 549, in cmd_query
    result = self._handle_result(self._send_cmd(ServerCmd.QUERY, query))
  File "D:\Programs\Python\Python37\lib\site-packages\mysql\connector\connection.py", line 438, in _handle_result
    raise errors.get_exception(packet)
mysql.connector.errors.IntegrityError: 1062 (23000): Duplicate entry 'rongshui' for key 'ix_user_username'

The above exception was the direct cause of the following exception:

Traceback (most recent call last):
  File "D:\Programs\Python\Python37\lib\site-packages\flask\app.py", line 2292, in wsgi_app
    response = self.full_dispatch_request()
  File "D:\Programs\Python\Python37\lib\site-packages\flask\app.py", line 1815, in full_dispatch_request
    rv = self.handle_user_exception(e)
  File "D:\Programs\Python\Python37\lib\site-packages\flask\app.py", line 1718, in handle_user_exception
    reraise(exc_type, exc_value, tb)
  File "D:\Programs\Python\Python37\lib\site-packages\flask\_compat.py", line 35, in reraise
    raise value
  File "D:\Programs\Python\Python37\lib\site-packages\flask\app.py", line 1813, in full_dispatch_request
    rv = self.dispatch_request()
  File "D:\Programs\Python\Python37\lib\site-packages\flask\app.py", line 1799, in dispatch_request
    return self.view_functions[rule.endpoint](**req.view_args)
  File "D:\Programs\Python\Python37\lib\site-packages\flask_login\utils.py", line 261, in decorated_view
    return func(*args, **kwargs)
  File "D:\PycharmProjects\flask_mega\microblog06\app_name\routes.py", line 94, in edit_profile
    db.session.commit()
  File "D:\Programs\Python\Python37\lib\site-packages\sqlalchemy\orm\scoping.py", line 153, in do
    return getattr(self.registry(), name)(*args, **kwargs)
  File "D:\Programs\Python\Python37\lib\site-packages\sqlalchemy\orm\session.py", line 943, in commit
    self.transaction.commit()
  File "D:\Programs\Python\Python37\lib\site-packages\sqlalchemy\orm\session.py", line 467, in commit
    self._prepare_impl()
  File "D:\Programs\Python\Python37\lib\site-packages\sqlalchemy\orm\session.py", line 447, in _prepare_impl
    self.session.flush()
  File "D:\Programs\Python\Python37\lib\site-packages\sqlalchemy\orm\session.py", line 2254, in flush
    self._flush(objects)
  File "D:\Programs\Python\Python37\lib\site-packages\sqlalchemy\orm\session.py", line 2380, in _flush
    transaction.rollback(_capture_exception=True)
  File "D:\Programs\Python\Python37\lib\site-packages\sqlalchemy\util\langhelpers.py", line 66, in __exit__
    compat.reraise(exc_type, exc_value, exc_tb)
  File "D:\Programs\Python\Python37\lib\site-packages\sqlalchemy\util\compat.py", line 249, in reraise
    raise value
  File "D:\Programs\Python\Python37\lib\site-packages\sqlalchemy\orm\session.py", line 2344, in _flush
    flush_context.execute()
  File "D:\Programs\Python\Python37\lib\site-packages\sqlalchemy\orm\unitofwork.py", line 391, in execute
    rec.execute(self)
  File "D:\Programs\Python\Python37\lib\site-packages\sqlalchemy\orm\unitofwork.py", line 556, in execute
    uow
  File "D:\Programs\Python\Python37\lib\site-packages\sqlalchemy\orm\persistence.py", line 177, in save_obj
    mapper, table, update)
  File "D:\Programs\Python\Python37\lib\site-packages\sqlalchemy\orm\persistence.py", line 768, in _emit_update_statements
    execute(statement, multiparams)
  File "D:\Programs\Python\Python37\lib\site-packages\sqlalchemy\engine\base.py", line 948, in execute
    return meth(self, multiparams, params)
  File "D:\Programs\Python\Python37\lib\site-packages\sqlalchemy\sql\elements.py", line 269, in _execute_on_connection
    return connection._execute_clauseelement(self, multiparams, params)
  File "D:\Programs\Python\Python37\lib\site-packages\sqlalchemy\engine\base.py", line 1060, in _execute_clauseelement
    compiled_sql, distilled_params
  File "D:\Programs\Python\Python37\lib\site-packages\sqlalchemy\engine\base.py", line 1200, in _execute_context
    context)
  File "D:\Programs\Python\Python37\lib\site-packages\sqlalchemy\engine\base.py", line 1413, in _handle_dbapi_exception
    exc_info
  File "D:\Programs\Python\Python37\lib\site-packages\sqlalchemy\util\compat.py", line 265, in raise_from_cause
    reraise(type(exception), exception, tb=exc_tb, cause=cause)
  File "D:\Programs\Python\Python37\lib\site-packages\sqlalchemy\util\compat.py", line 248, in reraise
    raise value.with_traceback(tb)
  File "D:\Programs\Python\Python37\lib\site-packages\sqlalchemy\engine\base.py", line 1193, in _execute_context
    context)
  File "D:\Programs\Python\Python37\lib\site-packages\sqlalchemy\engine\default.py", line 509, in do_execute
    cursor.execute(statement, parameters)
  File "D:\Programs\Python\Python37\lib\site-packages\mysql\connector\cursor.py", line 566, in execute
    self._handle_result(self._connection.cmd_query(stmt))
  File "D:\Programs\Python\Python37\lib\site-packages\mysql\connector\connection.py", line 549, in cmd_query
    result = self._handle_result(self._send_cmd(ServerCmd.QUERY, query))
  File "D:\Programs\Python\Python37\lib\site-packages\mysql\connector\connection.py", line 438, in _handle_result
    raise errors.get_exception(packet)
sqlalchemy.exc.IntegrityError: (mysql.connector.errors.IntegrityError) 1062 (23000): Duplicate entry 'rongshui' for key 'ix_user_username' [SQL: 'UPDATE user SET username=%(username)s, about_me=%(about_me)s WHERE user.id = %(user_id)s'] [parameters: {'username': 'rongshui', 'about_me': 'you are never alone!!!!', 'user_id': 1}] (Background on this error at: http://sqlalche.me/e/gkpj)
2018-10-07 17:11:37,384 INFO: Microblog startup [in D:\PycharmProjects\flask_mega\microblog06\app_name\__init__.py:28]
